<?xml version="1.0" encoding="utf-8"?>
<!-- This URDF was automatically created by SolidWorks to URDF Exporter! Originally created by Stephen Brawner (brawner@gmail.com) 
     Commit Version: 1.6.0-4-g7f85cfe  Build Version: 1.6.7995.38578
     For more information, please see http://wiki.ros.org/sw_urdf_exporter -->
<robot
  name="omni_car_bot">
  <link name="base_footprint"></link>

  <joint name="base_joint" type="fixed">
    <parent link="base_footprint"/>
    <child link="base_link"/>
    <origin xyz="0 0 0.12" rpy="0 0 0" />
  </joint>

  <link name="base_link">
    <inertial>
      <origin xyz="0 0 0" rpy="0 0 0" />
      <mass value="2.5" />
      <inertia
        ixx="0.01" ixy="0.0" ixz="0.0"
        iyy="0.02" iyz="0.0"
        izz="0.03" />
    </inertial>
    <visual>
      <origin
        xyz="0 0 0"
        rpy="0 0 0" />
      <geometry>
        <mesh
          filename="package://omni_car_bot/meshes/base_link.STL" />
      </geometry>
      <material
        name="">
        <color
          rgba="0.792156862745098 0.819607843137255 0.933333333333333 1" />
      </material>
    </visual>
<collision>
  <origin xyz="0 0 0" rpy="0 0 0" />
  <geometry>
    <box size="0.3 0.3 0.1"/>
  </geometry>
</collision>
  </link>
  
  <link name="imu_link">
  <visual>
    <geometry><box size="0.01 0.01 0.01"/></geometry>
  </visual>
  <collision>
    <geometry><box size="0.01 0.01 0.01"/></geometry>
  </collision>
  <inertial>
    <mass value="0.01"/>
    <inertia ixx="1e-6" ixy="0" ixz="0" iyy="1e-6" iyz="0" izz="1e-6"/>
  </inertial>
</link>

<joint name="imu_joint" type="fixed">
  <parent link="base_link"/>
  <child link="imu_link"/>
  <origin xyz="0 0 0.05" rpy="0 0 0"/>
</joint>
  
  <link name="gps_link"></link>
  
  <joint name="gps_joint" type="fixed">
  <parent link="base_link"/>
  <child link="gps_link"/>
  <origin xyz="0.1 0 0.08" rpy="0 0 0"/>
</joint>
  
<link name="FR_Link">
    <inertial>
      <origin xyz="-0.1 0.05 -.02" rpy="0 0 0"/>
      <mass value="0.5"/>
      <inertia ixx="0.0015" ixy="0" ixz="0" iyy="0.0028" iyz="0" izz="0.0015"/>
    </inertial>
    <visual>
      <origin xyz="-0.1 0.05 -.02" rpy="0 0 0"/>
      <geometry>
        <mesh filename="package://omni_car_bot/meshes/FR_Link.STL"/>
      </geometry>
    </visual>
    <collision>
      <origin xyz="-0.1 0.05 -.02" rpy="1.5707 0 0"/>
      <geometry>
        <cylinder radius="0.1075" length="0.05"/>
      </geometry>
    </collision>
  </link>

  <joint name="FR_Joint" type="continuous">
    <parent link="base_link"/>
    <child link="FR_Link"/>
    <origin xyz="0.2 -0.2 0" rpy="0 0 0"/>
    <axis xyz="0 1 0"/>
    <limit effort="100.0" velocity="10.0"/>
    <dynamics damping="0.7"/>
  </joint>
  
<link name="FL_Link">
    <inertial>
      <origin xyz="-0.1 -0.05 -.02" rpy="0 0 0"/>
      <mass value="0.5"/>
      <inertia ixx="0.0015" ixy="0" ixz="0" iyy="0.0028" iyz="0" izz="0.0015"/>
    </inertial>
    <visual>
      <origin xyz="-0.1 -0.05 -.02" rpy="0 0 0"/>
      <geometry>
        <mesh filename="package://omni_car_bot/meshes/FL_Link.STL"/>
      </geometry>
    </visual>
    <collision>
      <origin xyz="-0.1 -0.05 -.02" rpy="1.5707 0 0"/>
      <geometry>
        <cylinder radius="0.1075" length="0.05"/>
      </geometry>
    </collision>
  </link>

  <joint name="FL_Joint" type="continuous">
    <parent link="base_link"/>
    <child link="FL_Link"/>
    <origin xyz="0.2 0.2 0" rpy="0 0 0"/>
    <axis xyz="0 1 0"/>
    <limit effort="100.0" velocity="10.0"/>
    <dynamics damping="0.7"/>
  </joint>

  
<link name="BR_Link">
    <inertial>
      <origin xyz="0.1 0.05 -.02" rpy="0 0 0"/>
      <mass value="0.5"/>
      <inertia ixx="0.0015" ixy="0" ixz="0" iyy="0.0028" iyz="0" izz="0.0015"/>
    </inertial>
    <visual>
      <origin xyz="0.1 0.05 -.02" rpy="0 0 0"/>
      <geometry>
        <mesh filename="package://omni_car_bot/meshes/BR_Link.STL"/>
      </geometry>
    </visual>
    <collision>
      <origin xyz="0.1 0.05 -.02" rpy="1.5707 0 0"/>
      <geometry>
        <cylinder radius="0.1075" length="0.05"/>
      </geometry>
    </collision>
  </link>

  <joint name="BR_Joint" type="continuous">
    <parent link="base_link"/>
    <child link="BR_Link"/>
    <origin xyz="-0.2 -0.2 0" rpy="0 0 0"/>
    <axis xyz="0 1 0"/>
    <limit effort="100.0" velocity="10.0"/>
    <dynamics damping="0.7"/>
  </joint>
  
<link name="BL_Link">
    <inertial>
      <origin xyz="0.1 -0.05 -.02" rpy="0 0 0"/>
      <mass value="0.5"/>
      <inertia ixx="0.0015" ixy="0" ixz="0" iyy="0.0028" iyz="0" izz="0.0015"/>
    </inertial>
    <visual>
      <origin xyz="0.1 -0.05 -.02" rpy="0 0 0"/>
      <geometry>
        <mesh filename="package://omni_car_bot/meshes/BL_Link.STL"/>
      </geometry>
    </visual>
    <collision>
      <origin xyz="0.1 -0.05 -.02" rpy="1.5707 0 0"/>
      <geometry>
        <cylinder radius="0.1075" length="0.05"/>
      </geometry>
    </collision>
  </link>

  <joint name="BL_Joint" type="continuous">
    <parent link="base_link"/>
    <child link="BL_Link"/>
    <origin xyz="-0.2 0.2 0" rpy="0 0 0"/>
    <axis xyz="0 1 0"/>
    <limit effort="100.0" velocity="10.0"/>
    <dynamics damping="0.7"/>
  </joint>
  
  
  <transmission name="fr_transmission">
  <type>transmission_interface/SimpleTransmission</type>
  <joint name="FR_Joint">
    <hardwareInterface>hardware_interface/EffortJointInterface</hardwareInterface>
  </joint>
  <actuator name="fr_motor">
    <hardwareInterface>hardware_interface/EffortJointInterface</hardwareInterface>
    <mechanicalReduction>1</mechanicalReduction>
  </actuator>
</transmission>

<transmission name="fl_transmission">
  <type>transmission_interface/SimpleTransmission</type>
  <joint name="FL_Joint">
    <hardwareInterface>hardware_interface/EffortJointInterface</hardwareInterface>
  </joint>
  <actuator name="fl_motor">
    <hardwareInterface>hardware_interface/EffortJointInterface</hardwareInterface>
    <mechanicalReduction>1</mechanicalReduction>
  </actuator>
</transmission>

<transmission name="br_transmission">
  <type>transmission_interface/SimpleTransmission</type>
  <joint name="BR_Joint">
    <hardwareInterface>hardware_interface/EffortJointInterface</hardwareInterface>
  </joint>
  <actuator name="br_motor">
    <hardwareInterface>hardware_interface/EffortJointInterface</hardwareInterface>
    <mechanicalReduction>1</mechanicalReduction>
  </actuator>
</transmission>
  
<transmission name="bl_transmission">
  <type>transmission_interface/SimpleTransmission</type>
  <joint name="BL_Joint">
    <hardwareInterface>hardware_interface/EffortJointInterface</hardwareInterface>
  </joint>
  <actuator name="bl_motor">
    <hardwareInterface>hardware_interface/EffortJointInterface</hardwareInterface>
    <mechanicalReduction>1</mechanicalReduction>
  </actuator>
</transmission>
  

<gazebo>
  <plugin name="gazebo_ros_control" filename="libgazebo_ros_control.so">
    <robotNamespace>/</robotNamespace>
  </plugin>
</gazebo>

<gazebo reference="imu_link">
  <gravity>true</gravity>
  <sensor name="imu_sensor" type="imu">
    <always_on>true</always_on>
    <update_rate>100</update_rate>
    <visualize>true</visualize>
    <topic>/imu/data</topic>
  </sensor>
</gazebo>

<gazebo reference="gps_link">
  <sensor type="gps" name="gps_sensor">
    <always_on>true</always_on>
    <update_rate>1</update_rate>
    <visualize>false</visualize>
    <topic>/gps/fix</topic>
  </sensor>
</gazebo>

</robot>
